Workbook

Sheet Raw Platform Nov 4-6 2025
A1: OrderDate | B1: Hour | C1: OrderID | D1: Alternate_Id | E1: Restaurant | F1: Location | G1: Platform | H1: TotalSales
A2: Nov 6, 2025 | B2: 13.0 | C2: E3753 | D2: d311e99e-8294-4ea3-8a62-c7860c4e3753 | E2: Siam - Thai Kitchen | F2: NSK NRB | G2: Uber KE | H2: 1890.0
A3: Nov 6, 2025 | B3: 17.0 | C3: 66951 | D3: a1db4ea7-4976-49d8-aaba-6fbc0b766951 | E3: Siam - Thai Kitchen | F3: Village Market NRB | G3: Uber KE | H3: 2390.0
A4: Nov 6, 2025 | B4: 13.0 | C4: C851C | D4: 510b3a2f-1439-431f-a743-5196b35c851c | E4: Khan's - Pakistani Kitchen | F4: Westlands NRB | G4: Uber KE | H4: 1500.0
A5: Nov 6, 2025 | B5: 12.0 | C5: 17A3F | D5: 88bf6653-8268-4004-a679-5f5a19617a3f | E5: Little Italy | F5: Kilimani NRB | G5: Uber KE | H5: 2250.0
A6: Nov 6, 2025 | B6: 21.0 | C6: 360EA | D6: f23ed8a5-0965-4c75-a146-a9a71cd360ea | E6: DILLI! - Curries & Grill | F6: Kilimani NRB | G6: Uber KE | H6: 1140.0
A7: Nov 6, 2025 | B7: 18.0 | C7: 0D2F0 | D7: 4b934bbd-7fdf-4bf8-b220-0f587270d2f0 | E7: Kai Sushi Bar | F7: Village Market NRB | G7: Uber KE | H7: 7040.0
A8: Nov 6, 2025 | B8: 19.0 | C8: DD3D4 | D8: d390f304-1588-4c00-9af2-ea35084dd3d4 | E8: Marty's Famous Burgers | F8: Kilimani NRB | G8: Uber KE | H8: 2080.0
A9: Nov 6, 2025 | B9: 8.0 | C9: 088F9 | D9: b203c4ca-6fc4-4636-84a1-6c36dcb088f9 | E9: SuperWings | F9: null | G9: Uber KE | H9: 10260.0
A10: Nov 6, 2025 | B10: 9.0 | C10: 139333 | D10: 11986 | E10: Khan's - Pakistani Kitchen | F10: Westlands NRB | G10: ANDO App | H10: 920.0
A11: Nov 6, 2025 | B11: 18.0 | C11: 676E0 | D11: 0ee617a6-4279-489a-bab1-02e454f676e0 | E11: Pasta Della Nonna | F11: NSK NRB | G11: Uber KE | H11: 2200.0
A12: Nov 6, 2025 | B12: 12.0 | C12: 101477071505 | D12: 101477071505 | E12: Siam - Thai Kitchen | F12: NSK NRB | G12: Glovo | H12: 2780.0
... A1561: Nov 4, 2025 | B1561: 18.0 | C1561: 4E153 | D1561: d481e341-9515-4433-a42a-39386384e153 | E1561: Little Italy | F1561: Cape Town SA | G1561: Uber SA | H1561: 280.0

Sheet Glovo Raw Nov 4-6 2025
A1: Restaurant name | B1: Order ID | C1: Restaurant ID | D1: Delivery Type | E1: Payment type | F1: Payment method | G1: Is Pro Order | H1: Restaurant Address | I1: Order status | J1: Order received at | K1: Accepted at | L1: Estimated ready to pick up time | M1: Ready to pick up at | N1: Rider near pickup at | O1: In delivery at | P1: Estimated delivery time | Q1: Delivered at | R1: Has Complaint? | S1: Complaint Reason | T1: Cancelled at | U1: Cancellation reason | V1: Cancellation owner | W1: Subtotal | X1: Service fee | Y1: Packaging charges | Z1: Minimum order value fee | AA1: Rider Tip | AB1: Delivery Fee | AC1: Vendor Refunds | AD1: Tax Charge | AE1: Online Payment Fee | AF1: Discount Funded by Vendor | AG1: Voucher Funded by Vendor | AH1: Commission | AI1: Vendor Charges | AJ1: Ads Fee | AK1: Wait time fee | AL1: Marketing Fees | AM1: Is Payable | AN1: Is Paid | AO1: Estimated earnings | AP1: Cash amount already collected by vendor | AQ1: Amount owed back to platform | AR1: Payout Amount | AS1: Platform-Funded Discount | AT1: Platform-Funded Voucher | AU1: Total Discount | AV1: Total Voucher | AW1: Tax Amount | AX1: Order Items
A2: Little Italy (PQ5Q+2W Nairobi) [NBO] | B2: 1.01475401774E11 | C2: 212504.0 | D2: Vendor delivery | E2: Online | G2: N | H2: PQ5Q+2W Nairobi, Kenya | I2: Delivered | J2: 45965.47777777778 | K2: 45965.478472222225 | O2: 45965.50625 | P2: 45965.51597222222 | Q2: 45965.561111111114 | R2: N | W2: 1210.0 | X2: 0.0 | Y2: 0.0 | Z2: 0.0 | AA2: 0.0 | AB2: 200.0 | AC2: 0.0 | AD2: 0.0 | AE2: 0.0 | AF2: 0.0 | AG2: 0.0 | AH2: 0.0 | AI2: 0.0 | AJ2: 0.0 | AK2: 0.0 | AO2: 1410.0 | AP2: 0.0 | AQ2: 0.0 | AR2: 1410.0 | AS2: 0.0 | AT2: 0.0 | AU2: 0.0 | AV2: 0.0 | AW2: 0.0 | AX2: 1 Mother’s Lasagna [1 No Cutlery]
A3: Little Italy (PQ5Q+2W Nairobi) [NBO] | B3: 1.01475497632E11 | C3: 212504.0 | D3: Vendor delivery | E3: Online | G3: N | H3: PQ5Q+2W Nairobi, Kenya | I3: Delivered | J3: 45965.592361111114 | K3: 45965.592361111114 | O3: 45965.620833333334 | P3: 45965.63055555556 | Q3: 45965.67569444444 | R3: N | W3: 1350.0 | X3: 0.0 | Y3: 0.0 | Z3: 0.0 | AA3: 0.0 | AB3: 200.0 | AC3: 0.0 | AD3: 0.0 | AE3: 0.0 | AF3: 0.0 | AG3: 0.0 | AH3: 0.0 | AI3: 0.0 | AJ3: 0.0 | AK3: 0.0 | AO3: 1550.0 | AP3: 0.0 | AQ3: 0.0 | AR3: 1550.0 | AS3: 0.0 | AT3: 0.0 | AU3: 0.0 | AV3: 0.0 | AW3: 0.0 | AX3: 1 Tagliatelle w/ Mushroom Cream Sauce - Single Portion [1 Grilled Chicken, 1 No Cutlery]
A4: Little Italy (PQ5Q+2W Nairobi) [NBO] | B4: 1.01475749857E11 | C4: 212504.0 | D4: Vendor delivery | E4: Online | G4: Y | H4: PQ5Q+2W Nairobi, Kenya | I4: Delivered | J4: 45965.77638888889 | K4: 45965.77638888889 | O4: 45965.791666666664 | P4: 45965.813888888886 | Q4: 45965.85972222222 | R4: N | W4: 4190.0 | X4: 0.0 | Y4: 0.0 | Z4: 0.0 | AA4: 0.0 | AB4: 0.0 | AC4: 0.0 | AD4: 0.0 | AE4: 0.0 | AF4: 0.0 | AG4: 0.0 | AH4: 0.0 | AI4: 0.0 | AJ4: 0.0 | AK4: 0.0 | AO4: 4190.0 | AP4: 0.0 | AQ4: 0.0 | AR4: 4190.0 | AS4: 0.0 | AT4: 0.0 | AU4: 0.0 | AV4: 0.0 | AW4: 0.0 | AX4: 1 Penne Arrabbiata - Single Portion [1 No Cutlery], 1 Tagliatelle w/ Mushroom Cream Sauce - Single Portion [1 Grilled Chicken], 1 Creamy Chicken & Mushroom Macaroni - Single Portion [1 No Cutlery], 3 Pepsi Cola 300ml
A5: Little Italy (PQ5Q+2W Nairobi) [NBO] | B5: 1.01475768452E11 | C5: 212504.0 | D5: Vendor delivery | E5: Online | G5: N | H5: PQ5Q+2W Nairobi, Kenya | I5: Delivered | J5: 45965.790972222225 | K5: 45965.791666666664 | O5: 45965.80625 | P5: 45965.82916666667 | Q5: 45965.87708333333 | R5: N | W5: 1150.0 | X5: 0.0 | Y5: 0.0 | Z5: 0.0 | AA5: 0.0 | AB5: 200.0 | AC5: 0.0 | AD5: 0.0 | AE5: 0.0 | AF5: 0.0 | AG5: 0.0 | AH5: 0.0 | AI5: 0.0 | AJ5: 0.0 | AK5: 0.0 | AO5: 1350.0 | AP5: 0.0 | AQ5: 0.0 | AR5: 1350.0 | AS5: 0.0 | AT5: 0.0 | AU5: 0.0 | AV5: 0.0 | AW5: 0.0 | AX5: 1 Penne Arrabbiata - Single Portion [1 Grilled Chicken]
A6: Little Italy (PQ5Q+2W Nairobi) [NBO] | B6: 1.01475788395E11 | C6: 212504.0 | D6: Vendor delivery | E6: Online | G6: Y | H6: PQ5Q+2W Nairobi, Kenya | I6: Delivered | J6: 45965.80694444444 | K6: 45965.80763888889 | O6: 45965.84652777778 | P6: 45965.845138888886 | Q6: 45965.89097222222 | R6: N | W6: 4000.0 | X6: 0.0 | Y6: 0.0 | Z6: 0.0 | AA6: 0.0 | AB6: 0.0 | AC6: 0.0 | AD6: 0.0 | AE6: 0.0 | AF6: 0.0 | AG6: 0.0 | AH6: 0.0 | AI6: 0.0 | AJ6: 0.0 | AK6: 0.0 | AO6: 4000.0 | AP6: 0.0 | AQ6: 0.0 | AR6: 4000.0 | AS6: 0.0 | AT6: 0.0 | AU6: 0.0 | AV6: 0.0 | AW6: 0.0 | AX6: 2 Spaghetti Bolognese - Double Portion [1 No Cutlery]
A7: Little Italy (PQ5Q+2W Nairobi) [NBO] | B7: 1.01475830948E11 | C7: 212504.0 | D7: Vendor delivery | E7: Online | G7: Y | H7: PQ5Q+2W Nairobi, Kenya | I7: Delivered | J7: 45965.839583333334 | K7: 45965.84027777778 | O7: 45965.87777777778 | P7: 45965.87777777778 | Q7: 45965.92569444444 | R7: N | W7: 3180.0 | X7: 0.0 | Y7: 0.0 | Z7: 0.0 | AA7: 0.0 | AB7: 0.0 | AC7: 0.0 | AD7: 0.0 | AE7: 0.0 | AF7: 0.0 | AG7: 0.0 | AH7: 0.0 | AI7: 0.0 | AJ7: 0.0 | AK7: 0.0 | AO7: 3180.0 | AP7: 0.0 | AQ7: 0.0 | AR7: 3180.0 | AS7: 0.0 | AT7: 0.0 | AU7: 0.0 | AV7: 0.0 | AW7: 0.0 | AX7: 1 Tagliatelle w/ Mushroom Cream Sauce - Single Portion [1 No Cutlery], 1 Mac & Cheese - Kids' Portion [1 No Cutlery], 1 Kale Caesar Salad w/ Grilled Chicken
A8: Little Italy (PQ5Q+2W Nairobi) [NBO] | B8: 1.01475872386E11 | C8: 212504.0 | D8: Vendor delivery | E8: Online | G8: Y | H8: PQ5Q+2W Nairobi, Kenya | I8: Delivered | J8: 45965.86875 | K8: 45965.86944444444 | O8: 45965.88333333333 | P8: 45965.90694444445 | Q8: 45965.95347222222 | R8: N | W8: 2100.0 | X8: 0.0 | Y8: 0.0 | Z8: 0.0 | AA8: 0.0 | AB8: 0.0 | AC8: 0.0 | AD8: 0.0 | AE8: 0.0 | AF8: 0.0 | AG8: 0.0 | AH8: 0.0 | AI8: 0.0 | AJ8: 0.0 | AK8: 0.0 | AO8: 2100.0 | AP8: 0.0 | AQ8: 0.0 | AR8: 2100.0 | AS8: 0.0 | AT8: 0.0 | AU8: 0.0 | AV8: 0.0 | AW8: 0.0 | AX8: 1 Creamy Chicken & Mushroom Macaroni - Double Portion [1 No Cutlery]
A9: Little Italy (PQ5Q+2W Nairobi) [NBO] | B9: 1.01476291902E11 | C9: 212504.0 | D9: Vendor delivery | E9: Online | G9: N | H9: PQ5Q+2W Nairobi, Kenya | I9: Delivered | J9: 45966.58194444444 | K9: 45966.58194444444 | O9: 45966.60277777778 | P9: 45966.62013888889 | Q9: 45966.66527777778 | R9: N | W9: 5770.0 | X9: 0.0 | Y9: 0.0 | Z9: 0.0 | AA9: 0.0 | AB9: 200.0 | AC9: 0.0 | AD9: 0.0 | AE9: 0.0 | AF9: 0.0 | AG9: 0.0 | AH9: 0.0 | AI9: 0.0 | AJ9: 0.0 | AK9: 0.0 | AO9: 5970.0 | AP9: 0.0 | AQ9: 0.0 | AR9: 5970.0 | AS9: 0.0 | AT9: 0.0 | AU9: 0.0 | AV9: 0.0 | AW9: 0.0 | AX9: 1 Mother’s Lasagna [1 BPA-Free Cutlery], 2 Penne Alfredo - Double Portion [1 Grilled Chicken, 1 BPA-Free Cutlery]
A10: Little Italy (PQ5Q+2W Nairobi) [NBO] | B10: 1.01476440702E11 | C10: 212504.0 | D10: Vendor delivery | E10: Online | G10: N | H10: PQ5Q+2W Nairobi, Kenya | I10: Delivered | J10: 45966.67916666667 | K10: 45966.67986111111 | O10: 45966.728472222225 | P10: 45966.717361111114 | Q10: 45966.76597222222 | R10: N | W10: 2250.0 | X10: 0.0 | Y10: 0.0 | Z10: 0.0 | AA10: 0.0 | AB10: 200.0 | AC10: 0.0 | AD10: 0.0 | AE10: 0.0 | AF10: 0.0 | AG10: 0.0 | AH10: 0.0 | AI10: 0.0 | AJ10: 0.0 | AK10: 0.0 | AO10: 2450.0 | AP10: 0.0 | AQ10: 0.0 | AR10: 2450.0 | AS10: 0.0 | AT10: 0.0 | AU10: 0.0 | AV10: 0.0 | AW10: 0.0 | AX10: 1 Penne Alfredo - Double Portion [1 Grilled Chicken]
A11: Little Italy (PQ5Q+2W Nairobi) [NBO] | B11: 1.01476440949E11 | C11: 212504.0 | D11: Vendor delivery | E11: Cash | G11: N | H11: PQ5Q+2W Nairobi, Kenya | I11: Delivered | J11: 45966.67986111111 | K11: 45966.67986111111 | O11: 45966.728472222225 | P11: 45966.717361111114 | Q11: 45966.76597222222 | R11: N | W11: 1210.0 | X11: 0.0 | Y11: 0.0 | Z11: 0.0 | AA11: 0.0 | AB11: 200.0 | AC11: 0.0 | AD11: 0.0 | AE11: 0.0 | AF11: 0.0 | AG11: 0.0 | AH11: 0.0 | AI11: 0.0 | AJ11: 0.0 | AK11: 0.0 | AO11: 1458.4 | AP11: 1210.0 | AQ11: 0.0 | AR11: 248.4 | AS11: 0.0 | AT11: 0.0 | AU11: 0.0 | AV11: 0.0 | AW11: 0.0 | AX11: 1 Mother’s Lasagna
A12: Little Italy (PQ5Q+2W Nairobi) [NBO] | B12: 1.01476626016E11 | C12: 212504.0 | D12: Vendor delivery | E12: Online | G12: Y | H12: PQ5Q+2W Nairobi, Kenya | I12: Delivered | J12: 45966.82152777778 | K12: 45966.82152777778 | O12: 45966.856944444444 | P12: 45966.85972222222 | Q12: 45966.90555555555 | R12: N | W12: 2730.0 | X12: 0.0 | Y12: 0.0 | Z12: 0.0 | AA12: 0.0 | AB12: 0.0 | AC12: 0.0 | AD12: 0.0 | AE12: 0.0 | AF12: 0.0 | AG12: 0.0 | AH12: 0.0 | AI12: 0.0 | AJ12: 0.0 | AK12: 0.0 | AO12: 2730.0 | AP12: 0.0 | AQ12: 0.0 | AR12: 2730.0 | AS12: 0.0 | AT12: 0.0 | AU12: 0.0 | AV12: 0.0 | AW12: 0.0 | AX12: 1 Mac & Cheese Regular, 1 Kale Caesar Salad w/ Grilled Chicken
A13: Little Italy (PQ5Q+2W Nairobi) [NBO] | B13: 1.01476638371E11 | C13: 212504.0 | D13: Vendor delivery | E13: Online | G13: N | H13: PQ5Q+2W Nairobi, Kenya | I13: Delivered | J13: 45966.830555555556 | K13: 45966.830555555556 | O13: 45966.856944444444 | P13: 45966.86875 | Q13: 45966.91527777778 | R13: N | W13: 2280.0 | X13: 0.0 | Y13: 0.0 | Z13: 0.0 | AA13: 0.0 | AB13: 200.0 | AC13: 0.0 | AD13: 0.0 | AE13: 0.0 | AF13: 0.0 | AG13: 0.0 | AH13: 0.0 | AI13: 0.0 | AJ13: 0.0 | AK13: 0.0 | AO13: 2480.0 | AP13: 0.0 | AQ13: 0.0 | AR13: 2480.0 | AS13: 0.0 | AT13: 0.0 | AU13: 0.0 | AV13: 0.0 | AW13: 0.0 | AX13: 1 Classic Tiramisu, 1 Penne Arrabbiata - Single Portion [1 Grilled Chicken], 1 Creamy Chicken and Mushroom Soup
... A19: Little Italy (PQ5Q+2W Nairobi) [NBO] | B19: 1.01477432217E11 | C19: 212504.0 | D19: Vendor delivery | E19: Online | G19: Y | H19: PQ5Q+2W Nairobi, Kenya | I19: Delivered | J19: 45967.78611111111 | K19: 45967.78611111111 | O19: 45967.84444444445 | P19: 45967.82430555556 | Q19: 45967.87013888889 | R19: N | W19: 1700.0 | X19: 0.0 | Y19: 0.0 | Z19: 0.0 | AA19: 0.0 | AB19: 0.0 | AC19: 0.0 | AD19: 0.0 | AE19: 0.0 | AF19: 0.0 | AG19: 0.0 | AH19: 0.0 | AI19: 0.0 | AJ19: 0.0 | AK19: 0.0 | AO19: 1700.0 | AP19: 0.0 | AQ19: 0.0 | AR19: 1700.0 | AS19: 0.0 | AT19: 0.0 | AU19: 0.0 | AV19: 0.0 | AW19: 0.0 | AX19: 1 Chef's Special Tomato Soup, 1 Lasagna Vegetariana
A20: Khan's - Pakistani Kitchen (Mpaka Rd) [NBO] | B20: 1.01475688322E11 | C20: 265592.0 | D20: Vendor delivery | E20: Online | G20: Y | H20: Mpaka Rd, Nairobi, Kenya | I20: Cancelled | J20: 45965.72430555556 | K20: 45965.72430555556 | P20: 45965.7625 | R20: N | T20: 45965.76875 | U20: Incorrect address | V20: Customer | W20: 2220.0 | X20: 0.0 | Y20: 0.0 | Z20: 0.0 | AA20: 0.0 | AB20: 0.0 | AC20: 2220.0 | AD20: 0.0 | AE20: 0.0 | AF20: 0.0 | AG20: 0.0 | AH20: 0.0 | AI20: 0.0 | AJ20: 0.0 | AK20: 0.0 | AM20: yes | AO20: 2220.0 | AP20: 0.0 | AQ20: 0.0 | AR20: 2220.0 | AS20: 0.0 | AT20: 0.0 | AU20: 0.0 | AV20: 0.0 | AW20: 0.0 | AX20: 1 Chicken Tikka Roll, 1 Tandoori Garlic Naan, 1 Paneer Tikka Roll, 1 Lahori Halwa
A21: Khan's - Pakistani Kitchen (Mpaka Rd) [NBO] | B21: 1.01475753619E11 | C21: 265592.0 | D21: Vendor delivery | E21: Online | G21: Y | H21: Mpaka Rd, Nairobi, Kenya | I21: Delivered | J21: 45965.77916666667 | K21: 45965.77916666667 | O21: 45965.82013888889 | P21: 45965.81736111111 | Q21: 45965.86319444444 | R21: N | W21: 2220.0 | X21: 0.0 | Y21: 0.0 | Z21: 0.0 | AA21: 0.0 | AB21: 0.0 | AC21: 0.0 | AD21: 0.0 | AE21: 0.0 | AF21: 0.0 | AG21: 0.0 | AH21: 0.0 | AI21: 0.0 | AJ21: 0.0 | AK21: 0.0 | AO21: 2220.0 | AP21: 0.0 | AQ21: 0.0 | AR21: 2220.0 | AS21: 0.0 | AT21: 0.0 | AU21: 0.0 | AV21: 0.0 | AW21: 0.0 | AX21: 1 Chicken Tikka Roll, 1 Tandoori Garlic Naan, 1 Paneer Tikka Roll, 1 Lahori Halwa
A22: Khan's - Pakistani Kitchen (Mpaka Rd) [NBO] | B22: 1.01475915025E11 | C22: 265592.0 | D22: Vendor delivery | E22: Online | G22: Y | H22: Mpaka Rd, Nairobi, Kenya | I22: Delivered | J22: 45965.89444444444 | K22: 45965.89513888889 | O22: 45965.90416666667 | P22: 45965.93263888889 | Q22: 45965.978472222225 | R22: N | W22: 990.0 | X22: 0.0 | Y22: 0.0 | Z22: 0.0 | AA22: 0.0 | AB22: 0.0 | AC22: 0.0 | AD22: 0.0 | AE22: 0.0 | AF22: 0.0 | AG22: 0.0 | AH22: 0.0 | AI22: 0.0 | AJ22: 0.0 | AK22: 0.0 | AO22: 990.0 | AP22: 0.0 | AQ22: 0.0 | AR22: 990.0 | AS22: 0.0 | AT22: 0.0 | AU22: 0.0 | AV22: 0.0 | AW22: 0.0 | AX22: 1 Chicken Tikka Biryani [1 BPA-Free Cutlery, 2 Single Portion - Serves 1 Person]
A23: Khan's - Pakistani Kitchen (Mpaka Rd) [NBO] | B23: 1.01476217037E11 | C23: 265592.0 | D23: Vendor delivery | E23: Online | G23: N | H23: Mpaka Rd, Nairobi, Kenya | I23: Delivered | J23: 45966.495833333334 | K23: 45966.495833333334 | O23: 45966.51944444444 | P23: 45966.53402777778 | Q23: 45966.58194444444 | R23: N | W23: 970.0 | X23: 0.0 | Y23: 0.0 | Z23: 0.0 | AA23: 0.0 | AB23: 200.0 | AC23: 0.0 | AD23: 0.0 | AE23: 0.0 | AF23: 0.0 | AG23: 0.0 | AH23: 0.0 | AI23: 0.0 | AJ23: 0.0 | AK23: 0.0 | AO23: 1170.0 | AP23: 0.0 | AQ23: 0.0 | AR23: 1170.0 | AS23: 0.0 | AT23: 0.0 | AU23: 0.0 | AV23: 0.0 | AW23: 0.0 | AX23: 1 Sindhi Boneless Chicken Biryani [1 Mild, 1 Single Portion - Serves 1 Person]
A24: Khan's - Pakistani Kitchen (Mpaka Rd) [NBO] | B24: 1.01476244412E11 | C24: 265592.0 | D24: Vendor delivery | E24: Online | G24: N | H24: Mpaka Rd, Nairobi, Kenya | I24: Delivered | J24: 45966.53333333333 | K24: 45966.53402777778 | O24: 45966.55069444444 | P24: 45966.57152777778 | Q24: 45966.62013888889 | R24: N | W24: 920.0 | X24: 0.0 | Y24: 0.0 | Z24: 0.0 | AA24: 0.0 | AB24: 200.0 | AC24: 0.0 | AD24: 0.0 | AE24: 0.0 | AF24: 0.0 | AG24: 0.0 | AH24: 0.0 | AI24: 0.0 | AJ24: 0.0 | AK24: 0.0 | AO24: 1120.0 | AP24: 0.0 | AQ24: 0.0 | AR24: 1120.0 | AS24: 0.0 | AT24: 0.0 | AU24: 0.0 | AV24: 0.0 | AW24: 0.0 | AX24: 1 Sindhi Chicken Biryani [1 Single Portion - Serves 1 Person, 1 Mild]
A25: Khan's - Pakistani Kitchen (Mpaka Rd) [NBO] | B25: 1.0147635894E11 | C25: 265592.0 | D25: Vendor delivery | E25: Online | G25: N | H25: Mpaka Rd, Nairobi, Kenya | I25: Picked up | J25: 45966.629166666666 | K25: 45966.629166666666 | O25: 45966.72152777778 | P25: 45966.66736111111 | Q25: 45966.71388888889 | R25: N | W25: 2320.0 | X25: 0.0 | Y25: 0.0 | Z25: 0.0 | AA25: 0.0 | AB25: 200.0 | AC25: 0.0 | AD25: 0.0 | AE25: 0.0 | AF25: 0.0 | AG25: 0.0 | AH25: 0.0 | AI25: 0.0 | AJ25: 0.0 | AK25: 0.0 | AO25: 2520.0 | AP25: 0.0 | AQ25: 0.0 | AR25: 2520.0 | AS25: 0.0 | AT25: 0.0 | AU25: 0.0 | AV25: 0.0 | AW25: 0.0 | AX25: 1 Paneer Tikka Biryani [1 No Cutlery, 1 Single Portion - Serves 1 Person], 1 Lahori Chicken Karahi - Single Portion [1 Tandoori Garlic Naan]
A26: Khan's - Pakistani Kitchen (Mpaka Rd) [NBO] | B26: 1.01476595353E11 | C26: 265592.0 | D26: Vendor delivery | E26: Cash | G26: N | H26: Mpaka Rd, Nairobi, Kenya | I26: Delivered | J26: 45966.79791666667 | K26: 45966.79861111111 | O26: 45966.81319444445 | P26: 45966.83611111111 | Q26: 45966.88402777778 | R26: N | W26: 2910.0 | X26: 0.0 | Y26: 0.0 | Z26: 0.0 | AA26: 0.0 | AB26: 200.0 | AC26: 0.0 | AD26: 0.0 | AE26: 0.0 | AF26: 0.0 | AG26: 0.0 | AH26: 0.0 | AI26: 0.0 | AJ26: 0.0 | AK26: 0.0 | AO26: 3219.0 | AP26: 0.0 | AQ26: 0.0 | AR26: 3219.0 | AS26: 0.0 | AT26: 0.0 | AU26: 0.0 | AV26: 0.0 | AW26: 0.0 | AX26: 1 Sindhi Boneless Chicken Biryani [1 Mild, 1 Single Portion - Serves 1 Person], 2 Chicken Tikka Biryani [1 No Cutlery, 2 Single Portion - Serves 1 Person]
A27: Khan's - Pakistani Kitchen (Mpaka Rd) [NBO] | B27: 1.01476630542E11 | C27: 265592.0 | D27: Vendor delivery | E27: Online | G27: N | H27: Mpaka Rd, Nairobi, Kenya | I27: Delivered | J27: 45966.82430555556 | K27: 45966.825 | O27: 45966.84652777778 | P27: 45966.8625 | Q27: 45966.90833333333 | R27: N | W27: 1250.0 | X27: 0.0 | Y27: 0.0 | Z27: 0.0 | AA27: 0.0 | AB27: 200.0 | AC27: 0.0 | AD27: 0.0 | AE27: 0.0 | AF27: 0.0 | AG27: 0.0 | AH27: 0.0 | AI27: 0.0 | AJ27: 0.0 | AK27: 0.0 | AO27: 1450.0 | AP27: 0.0 | AQ27: 0.0 | AR27: 1450.0 | AS27: 0.0 | AT27: 0.0 | AU27: 0.0 | AV27: 0.0 | AW27: 0.0 | AX27: 1 Chicken Tikka Roll, 1 Gulab Jamun
A28: Khan's - Pakistani Kitchen (Mpaka Rd) [NBO] | B28: 1.01476636956E11 | C28: 265592.0 | D28: Vendor delivery | E28: Online | G28: Y | H28: Mpaka Rd, Nairobi, Kenya | I28: Delivered | J28: 45966.82916666667 | K28: 45966.82916666667 | O28: 45966.84652777778 | P28: 45966.86736111111 | Q28: 45966.91527777778 | R28: N | W28: 1940.0 | X28: 0.0 | Y28: 0.0 | Z28: 0.0 | AA28: 0.0 | AB28: 0.0 | AC28: 0.0 | AD28: 0.0 | AE28: 0.0 | AF28: 0.0 | AG28: 0.0 | AH28: 0.0 | AI28: 0.0 | AJ28: 0.0 | AK28: 0.0 | AO28: 1940.0 | AP28: 0.0 | AQ28: 0.0 | AR28: 1940.0 | AS28: 0.0 | AT28: 0.0 | AU28: 0.0 | AV28: 0.0 | AW28: 0.0 | AX28: 2 Chicken Tikka Biryani [1 No Cutlery, 1 Single Portion - Serves 1 Person]
A29: Khan's - Pakistani Kitchen (Mpaka Rd) [NBO] | B29: 1.01477091498E11 | C29: 265592.0 | D29: Vendor delivery | E29: Online | G29: N | H29: Mpaka Rd, Nairobi, Kenya | I29: Delivered | J29: 45967.53888888889 | K29: 45967.53888888889 | O29: 45967.544444444444 | P29: 45967.57708333333 | Q29: 45967.623611111114 | R29: N | W29: 970.0 | X29: 0.0 | Y29: 0.0 | Z29: 0.0 | AA29: 0.0 | AB29: 200.0 | AC29: 0.0 | AD29: 0.0 | AE29: 0.0 | AF29: 0.0 | AG29: 0.0 | AH29: 0.0 | AI29: 0.0 | AJ29: 0.0 | AK29: 0.0 | AO29: 1170.0 | AP29: 0.0 | AQ29: 0.0 | AR29: 1170.0 | AS29: 0.0 | AT29: 0.0 | AU29: 0.0 | AV29: 0.0 | AW29: 0.0 | AX29: 1 Chicken Tikka Biryani [1 No Cutlery, 1 Single Portion - Serves 1 Person]
A30: Khan's - Pakistani Kitchen (Mpaka Rd) [NBO] | B30: 1.01477093687E11 | C30: 265592.0 | D30: Vendor delivery | E30: Online | G30: N | H30: Mpaka Rd, Nairobi, Kenya | I30: Delivered | J30: 45967.541666666664 | K30: 45967.541666666664 | O30: 45967.544444444444 | P30: 45967.57986111111 | Q30: 45967.62708333333 | R30: N | W30: 1410.0 | X30: 0.0 | Y30: 0.0 | Z30: 0.0 | AA30: 0.0 | AB30: 200.0 | AC30: 0.0 | AD30: 0.0 | AE30: 0.0 | AF30: 0.0 | AG30: 0.0 | AH30: 0.0 | AI30: 0.0 | AJ30: 0.0 | AK30: 0.0 | AO30: 1610.0 | AP30: 0.0 | AQ30: 0.0 | AR30: 1610.0 | AS30: 0.0 | AT30: 0.0 | AU30: 0.0 | AV30: 0.0 | AW30: 0.0 | AX30: 1 Mutton Karahi - Single Portion [1 Tandoori Butter Naan]
A31: Khan's - Pakistani Kitchen (Mpaka Rd) [NBO] | B31: 1.01477454686E11 | C31: 265592.0 | D31: Vendor delivery | E31: Online | G31: Y | H31: Mpaka Rd, Nairobi, Kenya | I31: Delivered | J31: 45967.802777777775 | K31: 45967.80347222222 | O31: 45967.83541666667 | P31: 45967.84097222222 | Q31: 45967.8875 | R31: N | W31: 970.0 | X31: 0.0 | Y31: 0.0 | Z31: 0.0 | AA31: 0.0 | AB31: 0.0 | AC31: 0.0 | AD31: 0.0 | AE31: 0.0 | AF31: 0.0 | AG31: 0.0 | AH31: 0.0 | AI31: 0.0 | AJ31: 0.0 | AK31: 0.0 | AO31: 970.0 | AP31: 0.0 | AQ31: 0.0 | AR31: 970.0 | AS31: 0.0 | AT31: 0.0 | AU31: 0.0 | AV31: 0.0 | AW31: 0.0 | AX31: 1 Chicken Tikka Biryani [1 No Cutlery, 1 Single Portion - Serves 1 Person]
A32: Khan's - Pakistani Kitchen (Mpaka Rd) [NBO] | B32: 1.01477463665E11 | C32: 265592.0 | D32: Vendor delivery | E32: Online | G32: N | H32: Mpaka Rd, Nairobi, Kenya | I32: Delivered | J32: 45967.80902777778 | K32: 45967.80972222222 | O32: 45967.85277777778 | P32: 45967.84722222222 | Q32: 45967.89444444444 | R32: N | W32: 860.0 | X32: 0.0 | Y32: 0.0 | Z32: 0.0 | AA32: 0.0 | AB32: 200.0 | AC32: 0.0 | AD32: 0.0 | AE32: 0.0 | AF32: 0.0 | AG32: 0.0 | AH32: 0.0 | AI32: 0.0 | AJ32: 0.0 | AK32: 0.0 | AO32: 1060.0 | AP32: 0.0 | AQ32: 0.0 | AR32: 1060.0 | AS32: 0.0 | AT32: 0.0 | AU32: 0.0 | AV32: 0.0 | AW32: 0.0 | AX32: 2 Gulab Jamun
... A42: Khan's - Pakistani Kitchen (Village Market) [NBO] | B42: 1.01475877409E11 | C42: 378030.0 | D42: Vendor delivery | E42: Cash | G42: N | H42: Village Market, Nairobi, Kenya | I42: Delivered | J42: 45965.87222222222 | K42: 45965.87222222222 | O42: 45965.90347222222 | P42: 45965.910416666666 | Q42: 45965.95694444444 | R42: N | W42: 970.0 | X42: 0.0 | Y42: 0.0 | Z42: 0.0 | AA42: 0.0 | AB42: 0.0 | AC42: 0.0 | AD42: 0.0 | AE42: 0.0 | AF42: 0.0 | AG42: 0.0 | AH42: 0.0 | AI42: 0.0 | AJ42: 0.0 | AK42: 0.0 | AO42: 989.4 | AP42: 0.0 | AQ42: 0.0 | AR42: 989.4 | AS42: 0.0 | AT42: 0.0 | AU42: 0.0 | AV42: 0.0 | AW42: 0.0 | AX42: 1 Sindhi Boneless Chicken Biryani [1 Spicy (hot), 1 Single Portion - Serves 1 Person]
A43: DILLI! - Curries and Grill (Village Market) [NBO] | B43: 1.01475781046E11 | C43: 378071.0 | D43: Platform delivery | E43: Online | G43: N | H43: Village Market, Nairobi, Kenya | I43: Delivered | J43: 45965.80138888889 | K43: 45965.80138888889 | L43: 45965.81319444445 | M43: 45965.81319444445 | N43: 45965.80763888889 | O43: 45965.81319444445 | P43: 45965.83263888889 | Q43: 45965.82777777778 | R43: N | W43: 1270.0 | X43: 0.0 | Y43: 0.0 | Z43: 0.0 | AA43: 0.0 | AB43: 0.0 | AC43: 0.0 | AD43: 0.0 | AE43: 0.0 | AF43: 0.0 | AG43: 0.0 | AH43: 0.0 | AI43: 0.0 | AJ43: 0.0 | AK43: 0.0 | AO43: 1270.0 | AP43: 0.0 | AQ43: 0.0 | AR43: 1270.0 | AS43: 0.0 | AT43: 0.0 | AU43: 0.0 | AV43: 0.0 | AW43: 0.0 | AX43: 1 Tandoori Garlic Naan, 1 Dilliwala Butter Chicken [1 Tandoori Garlic Naan, 1 Single Portion - Serves 1, 1 Hot, 1 BPA-Free Cutlery]
A44: DILLI! - Curries and Grill (Village Market) [NBO] | B44: 1.01477434883E11 | C44: 378071.0 | D44: Platform delivery | E44: Online | G44: N | H44: Village Market, Nairobi, Kenya | I44: Delivered | J44: 45967.794444444444 | K44: 45967.794444444444 | L44: 45967.80486111111 | N44: 45967.80138888889 | O44: 45967.80625 | P44: 45967.82986111111 | Q44: 45967.82013888889 | R44: N | W44: 990.0 | X44: 0.0 | Y44: 0.0 | Z44: 0.0 | AA44: 0.0 | AB44: 0.0 | AC44: 0.0 | AD44: 0.0 | AE44: 0.0 | AF44: 0.0 | AG44: 0.0 | AH44: 0.0 | AI44: 0.0 | AJ44: 0.0 | AK44: 0.0 | AO44: 990.0 | AP44: 0.0 | AQ44: 0.0 | AR44: 990.0 | AS44: 0.0 | AT44: 0.0 | AU44: 0.0 | AV44: 0.0 | AW44: 0.0 | AX44: 1 Dilliwala Butter Chicken - Single Portion [1 Tandoori Garlic Naan, 1 Mild, 1 No Cutlery]
A45: DILLI! - Curries and Grill (Village Market) [NBO] | B45: 1.0147747393E11 | C45: 378071.0 | D45: Platform delivery | E45: Online | G45: N | H45: Village Market, Nairobi, Kenya | I45: Delivered | J45: 45967.81805555556 | K45: 45967.81805555556 | L45: 45967.82986111111 | N45: 45967.82638888889 | O45: 45967.82986111111 | P45: 45967.847916666666 | Q45: 45967.84652777778 | R45: N | W45: 1270.0 | X45: 0.0 | Y45: 0.0 | Z45: 0.0 | AA45: 0.0 | AB45: 0.0 | AC45: 0.0 | AD45: 0.0 | AE45: 0.0 | AF45: 0.0 | AG45: 0.0 | AH45: 0.0 | AI45: 0.0 | AJ45: 0.0 | AK45: 0.0 | AO45: 1270.0 | AP45: 0.0 | AQ45: 0.0 | AR45: 1270.0 | AS45: 0.0 | AT45: 0.0 | AU45: 0.0 | AV45: 0.0 | AW45: 0.0 | AX45: 1 Tandoori Garlic Naan, 1 Chicken Tikka Masala - Single Portion [1 Tandoori Garlic Naan, 1 Medium, 1 BPA-Free Cutlery]
A46: SuperWings (PQ5Q+2J8) [NBO] | B46: 1.01475412871E11 | C46: 475401.0 | D46: Vendor delivery | E46: Online | G46: N | H46: PQ5Q+2J8, Timau Road, Nairobi, Kenya | I46: Delivered | J46: 45965.49722222222 | K46: 45965.49791666667 | O46: 45965.52777777778 | P46: 45965.535416666666 | Q46: 45965.58194444444 | R46: N | W46: 850.0 | X46: 0.0 | Y46: 0.0 | Z46: 0.0 | AA46: 0.0 | AB46: 200.0 | AC46: 0.0 | AD46: 0.0 | AE46: 0.0 | AF46: 0.0 | AG46: 0.0 | AH46: 0.0 | AI46: 0.0 | AJ46: 0.0 | AK46: 0.0 | AO46: 1050.0 | AP46: 0.0 | AQ46: 0.0 | AR46: 1050.0 | AS46: 0.0 | AT46: 0.0 | AU46: 0.0 | AV46: 0.0 | AW46: 0.0 | AX46: 1 Traditional Buffalo Wings (Bone-in) [1 6pcs]
A47: SuperWings (PQ5Q+2J8) [NBO] | B47: 1.01475537113E11 | C47: 475401.0 | D47: Vendor delivery | E47: Online | G47: N | H47: PQ5Q+2J8, Timau Road, Nairobi, Kenya | I47: Delivered | J47: 45965.620833333334 | K47: 45965.620833333334 | O47: 45965.63958333333 | P47: 45965.65833333333 | Q47: 45965.70347222222 | R47: N | W47: 2400.0 | X47: 0.0 | Y47: 0.0 | Z47: 0.0 | AA47: 0.0 | AB47: 200.0 | AC47: 0.0 | AD47: 0.0 | AE47: 0.0 | AF47: 0.0 | AG47: 0.0 | AH47: 0.0 | AI47: 0.0 | AJ47: 0.0 | AK47: 0.0 | AO47: 2600.0 | AP47: 0.0 | AQ47: 0.0 | AR47: 2600.0 | AS47: 0.0 | AT47: 0.0 | AU47: 0.0 | AV47: 0.0 | AW47: 0.0 | AX47: 1 Teriyaki Wings (Boneless) [1 24pc]
A48: SuperWings (PQ5Q+2J8) [NBO] | B48: 1.01476318076E11 | C48: 475401.0 | D48: Vendor delivery | E48: Cash | G48: N | H48: PQ5Q+2J8, Timau Road, Nairobi, Kenya | I48: Delivered | J48: 45966.60208333333 | K48: 45966.60208333333 | O48: 45966.64375 | P48: 45966.64027777778 | Q48: 45966.686111111114 | R48: N | W48: 1750.0 | X48: 0.0 | Y48: 0.0 | Z48: 0.0 | AA48: 0.0 | AB48: 200.0 | AC48: 0.0 | AD48: 0.0 | AE48: 0.0 | AF48: 0.0 | AG48: 0.0 | AH48: 0.0 | AI48: 0.0 | AJ48: 0.0 | AK48: 0.0 | AO48: 2020.0 | AP48: 0.0 | AQ48: 0.0 | AR48: 2020.0 | AS48: 0.0 | AT48: 0.0 | AU48: 0.0 | AV48: 0.0 | AW48: 0.0 | AX48: 1 Honey Mustard Wings (Boneless) [1 12pcs, 1 Add Classic Fries]
A49: SuperWings (PQ5Q+2J8) [NBO] | B49: 1.01477412193E11 | C49: 475401.0 | D49: Vendor delivery | E49: Online | G49: Y | H49: PQ5Q+2J8, Timau Road, Nairobi, Kenya | I49: Delivered | J49: 45967.770833333336 | K49: 45967.770833333336 | O49: 45967.8 | P49: 45967.80902777778 | Q49: 45967.85625 | R49: N | W49: 1150.0 | X49: 0.0 | Y49: 0.0 | Z49: 0.0 | AA49: 0.0 | AB49: 0.0 | AC49: 0.0 | AD49: 0.0 | AE49: 0.0 | AF49: 0.0 | AG49: 0.0 | AH49: 0.0 | AI49: 0.0 | AJ49: 0.0 | AK49: 0.0 | AO49: 1150.0 | AP49: 0.0 | AQ49: 0.0 | AR49: 1150.0 | AS49: 0.0 | AT49: 0.0 | AU49: 0.0 | AV49: 0.0 | AW49: 0.0 | AX49: 1 Korean-style Sweet & Spicy Wings (Boneless) [1 Add Classic Fries, 1 Ranch Dressing, 1 6pc]
A50: SuperWings (PRM3+FHW) [NBO] | B50: 1.01477498999E11 | C50: 499193.0 | D50: Vendor delivery | E50: Cash | G50: N | H50: PRM3+FHW, Nairobi, Kenya | I50: Delivered | J50: 45967.834027777775 | K50: 45967.83472222222 | O50: 45967.853472222225 | P50: 45967.87222222222 | Q50: 45967.91875 | R50: N | W50: 1550.0 | X50: 0.0 | Y50: 0.0 | Z50: 0.0 | AA50: 0.0 | AB50: 0.0 | AC50: 0.0 | AD50: 0.0 | AE50: 0.0 | AF50: 0.0 | AG50: 0.0 | AH50: 0.0 | AI50: 0.0 | AJ50: 0.0 | AK50: 0.0 | AO50: 1612.0 | AP50: 0.0 | AQ50: 0.0 | AR50: 1612.0 | AS50: 0.0 | AT50: 0.0 | AU50: 0.0 | AV50: 0.0 | AW50: 0.0 | AX50: 1 Teriyaki Wings (Bone-In) [1 12pc]
A51: Marty’s Famous Burgers (Timau Plaza) [NBO] | B51: 1.01475777555E11 | C51: 516342.0 | D51: Vendor delivery | E51: Cash | G51: N | H51: Timau Plaza, Nairobi, Kenya | I51: Delivered | J51: 45965.79861111111 | K51: 45965.79861111111 | O51: 45965.84652777778 | P51: 45965.836805555555 | Q51: 45965.88402777778 | R51: N | W51: 1900.0 | X51: 0.0 | Y51: 0.0 | Z51: 0.0 | AA51: 0.0 | AB51: 200.0 | AC51: 0.0 | AD51: 0.0 | AE51: 0.0 | AF51: 0.0 | AG51: 0.0 | AH51: 0.0 | AI51: 0.0 | AJ51: 0.0 | AK51: 0.0 | AO51: 2176.0 | AP51: 0.0 | AQ51: 0.0 | AR51: 2176.0 | AS51: 0.0 | AT51: 0.0 | AU51: 0.0 | AV51: 0.0 | AW51: 0.0 | AX51: 1 Marty's Shroom Special Classic, 1 Lemon Pepper Wings (Boneless)
A52: Marty’s Famous Burgers (Timau Plaza) [NBO] | B52: 1.01476719935E11 | C52: 516342.0 | D52: Vendor delivery | E52: Cash | G52: N | H52: Timau Plaza, Nairobi, Kenya | I52: Delivered | J52: 45966.88333333333 | K52: 45966.88333333333 | O52: 45966.89444444444 | P52: 45966.92152777778 | Q52: 45966.967361111114 | R52: N | W52: 2390.0 | X52: 0.0 | Y52: 0.0 | Z52: 0.0 | AA52: 0.0 | AB52: 200.0 | AC52: 0.0 | AD52: 0.0 | AE52: 0.0 | AF52: 0.0 | AG52: 0.0 | AH52: 0.0 | AI52: 0.0 | AJ52: 0.0 | AK52: 0.0 | AO52: 2685.6 | AP52: 0.0 | AQ52: 0.0 | AR52: 2685.6 | AS52: 0.0 | AT52: 0.0 | AU52: 0.0 | AV52: 0.0 | AW52: 0.0 | AX52: 1 Marty's Double Cheeseburger Classic, 1 Marty's Famous Cheeseburger Regular [1 Add Classic Fries], 1 Pepsi Cola 300ml
A53: Marty’s Famous Burgers (Timau Plaza) [NBO] | B53: 1.01477249215E11 | C53: 516342.0 | D53: Vendor delivery | E53: Online | G53: Y | H53: Timau Plaza, Nairobi, Kenya | I53: Delivered | J53: 45967.65694444445 | K53: 45967.65694444445 | O53: 45967.67361111111 | P53: 45967.69513888889 | Q53: 45967.686111111114 | R53: N | W53: 1490.0 | X53: 0.0 | Y53: 0.0 | Z53: 0.0 | AA53: 0.0 | AB53: 0.0 | AC53: 0.0 | AD53: 0.0 | AE53: 0.0 | AF53: 0.0 | AG53: 0.0 | AH53: 0.0 | AI53: 0.0 | AJ53: 0.0 | AK53: 0.0 | AO53: 1490.0 | AP53: 0.0 | AQ53: 0.0 | AR53: 1490.0 | AS53: 0.0 | AT53: 0.0 | AU53: 0.0 | AV53: 0.0 | AW53: 0.0 | AX53: 1 Minty Melonade, 1 Marty’s Famous Cheeseburger (Regular) + Classic Fries + Pepsi
A54: Marty’s Famous Burgers (Timau Plaza) [NBO] | B54: 1.0147745502E11 | C54: 516342.0 | D54: Vendor delivery | E54: Online | G54: N | H54: Timau Plaza, Nairobi, Kenya | I54: Delivered | J54: 45967.80347222222 | K54: 45967.80347222222 | O54: 45967.84444444445 | P54: 45967.84166666667 | Q54: 45967.8875 | R54: N | W54: 1100.0 | X54: 0.0 | Y54: 0.0 | Z54: 0.0 | AA54: 0.0 | AB54: 200.0 | AC54: 0.0 | AD54: 0.0 | AE54: 0.0 | AF54: 0.0 | AG54: 0.0 | AH54: 0.0 | AI54: 0.0 | AJ54: 0.0 | AK54: 0.0 | AO54: 1300.0 | AP54: 0.0 | AQ54: 0.0 | AR54: 1300.0 | AS54: 0.0 | AT54: 0.0 | AU54: 0.0 | AV54: 0.0 | AW54: 0.0 | AX54: 1 Marty’s Famous Cheeseburger (Regular) + Classic Fries + Pepsi
...

Sheet Auditing Nov 4-6 2025
A1: kitchen_code | B1: rider_username | C1: rider_name | D1: kitchen_name | E1: status | F1: order_id | G1: validated_id | H1: duplicate | I1: order_accepted_time | J1: order_source | K1: payment_status | L1: customer_name | M1: customer_number | N1: customer_address | O1: estimated_delivery_time | P1: estimated_delivery_distance | Q1: order_amount | R1: vehicle_type | S1: brand_name | T1: is_bulk | U1: is_earnings_processed | V1: assigned_at | W1: rejected_at | X1: delivery_fees
A2: nsk | B2: +2540794092505 | C2: Abdulaziz Juma Ebikes | D2: NSK NRB | E2: COMPLETED | F2: A6DF5 | G2: =IF(K2="Pick-up","PICKUPS",IF(K2="Staff drop-off","STAFF_DROPOFF",IF(K2="Replacements","REPLACEMENT",IF(K2="Central Stores Dispatch","CENTRAL STORES DISPATCH",IFNA(IFNA(VLOOKUP(F2,'Raw Platform Nov 4-6 2025'!C:C,1,FALSE),VLOOKUP(F2,'Raw Platform Nov 4-6 2025'!D:D,1,FALSE)),IFNA(VLOOKUP(F2,'Glovo Raw Nov 4-6 2025'!B:B,1,FALSE),"Not Matched")))))) | H2: =COUNTIF(F:F,F2) | I2: Nov 6, 2025, 9:45:14 PM | J2: Uber Eats | K2: UNPAID | L2: AMAURY F | M2: 0758992983 | N2: Westlands place apartments, Westlands Close, Nairobi, Kenya | O2: 2.0 | P2: 0.4 | Q2: 1960 | R2: BICYCLE | S2: Siam - Thai Kitchen | T2: false | U2: true | V2: Nov 6, 2025, 10:01:02 PM | X2: 0
A3: nsk | B3: +2540794092505 | C3: Abdulaziz Juma Ebikes | D3: NSK NRB | E3: COMPLETED | F3: 853EC | G3: =IF(K3="Pick-up","PICKUPS",IF(K3="Staff drop-off","STAFF_DROPOFF",IF(K3="Replacements","REPLACEMENT",IF(K3="Central Stores Dispatch","CENTRAL STORES DISPATCH",IFNA(IFNA(VLOOKUP(F3,'Raw Platform Nov 4-6 2025'!C:C,1,FALSE),VLOOKUP(F3,'Raw Platform Nov 4-6 2025'!D:D,1,FALSE)),IFNA(VLOOKUP(F3,'Glovo Raw Nov 4-6 2025'!B:B,1,FALSE),"Not Matched")))))) | H3: =COUNTIF(F:F,F3) | I3: Nov 6, 2025, 9:30:09 PM | J3: Uber Eats | K3: PAID | L3: CATIA P | M3: 0758992983 | N3: MP Shah Hospital, Shivachi Road, Nairobi, Kenya | O3: 7.0 | P3: 1.4 | Q3: 0 | R3: BICYCLE | S3: Siam - Thai Kitchen | T3: false | U3: true | V3: Nov 6, 2025, 9:47:37 PM | X3: 0
A4: nsk-copy | B4: +2540794092505 | C4: Abdulaziz Juma Ebikes | D4: NSK NRB | E4: COMPLETED | F4: 101477539337 | G4: =IF(K4="Pick-up","PICKUPS",IF(K4="Staff drop-off","STAFF_DROPOFF",IF(K4="Replacements","REPLACEMENT",IF(K4="Central Stores Dispatch","CENTRAL STORES DISPATCH",IFNA(IFNA(VLOOKUP(F4,'Raw Platform Nov 4-6 2025'!C:C,1,FALSE),VLOOKUP(F4,'Raw Platform Nov 4-6 2025'!D:D,1,FALSE)),IFNA(VLOOKUP(F4,'Glovo Raw Nov 4-6 2025'!B:B,1,FALSE),"Not Matched")))))) | H4: =COUNTIF(F:F,F4) | I4: Nov 6, 2025, 8:58:03 PM | J4: Glovo | K4: PAID | L4: MHMD | M4: 0792472323 | N4: Capital M Residences - LEED Certified, Muthithi Road, Nairobi, Kenya | O4: 2.0 | P4: 0.5 | Q4: 0 | R4: BICYCLE | S4: Little Italy | T4: false | U4: true | V4: Nov 6, 2025, 8:59:04 PM | X4: 0
A5: nsk | B5: +2540794092505 | C5: Abdulaziz Juma Ebikes | D5: NSK NRB | E5: COMPLETED | F5: FED45 | G5: =IF(K5="Pick-up","PICKUPS",IF(K5="Staff drop-off","STAFF_DROPOFF",IF(K5="Replacements","REPLACEMENT",IF(K5="Central Stores Dispatch","CENTRAL STORES DISPATCH",IFNA(IFNA(VLOOKUP(F5,'Raw Platform Nov 4-6 2025'!C:C,1,FALSE),VLOOKUP(F5,'Raw Platform Nov 4-6 2025'!D:D,1,FALSE)),IFNA(VLOOKUP(F5,'Glovo Raw Nov 4-6 2025'!B:B,1,FALSE),"Not Matched")))))) | H5: =COUNTIF(F:F,F5) | I5: Nov 6, 2025, 7:36:38 PM | J5: Uber Eats | K5: PAID | L5: STEPHANIE P | M5: 0745420817 | N5: CMM Gardens, Rhapta Road, Nairobi, Kenya | O5: 7.0 | P5: 2.8 | Q5: 0 | R5: BICYCLE | S5: Siam - Thai Kitchen | T5: false | U5: true | V5: Nov 6, 2025, 8:07:29 PM | X5: 0
A6: nsk | B6: +2540794092505 | C6: Abdulaziz Juma Ebikes | D6: NSK NRB | E6: COMPLETED | F6: 101477472920 | G6: =IF(K6="Pick-up","PICKUPS",IF(K6="Staff drop-off","STAFF_DROPOFF",IF(K6="Replacements","REPLACEMENT",IF(K6="Central Stores Dispatch","CENTRAL STORES DISPATCH",IFNA(IFNA(VLOOKUP(F6,'Raw Platform Nov 4-6 2025'!C:C,1,FALSE),VLOOKUP(F6,'Raw Platform Nov 4-6 2025'!D:D,1,FALSE)),IFNA(VLOOKUP(F6,'Glovo Raw Nov 4-6 2025'!B:B,1,FALSE),"Not Matched")))))) | H6: =COUNTIF(F:F,F6) | I6: Nov 6, 2025, 7:35:09 PM | J6: Glovo | K6: PAID | L6: IBRAHIM K | M6: 0759158120 | N6: Orchid Residency by Kaisa, Nairobi, Kenya | O6: 5.0 | P6: 2.1 | Q6: 0 | R6: BICYCLE | S6: Siam - Thai Kitchen | T6: false | U6: true | V6: Nov 6, 2025, 8:05:52 PM | X6: 0
A7: nsk-copy | B7: +2540794092505 | C7: Abdulaziz Juma Ebikes | D7: NSK NRB | E7: COMPLETED | F7: 501D9 | G7: =IF(K7="Pick-up","PICKUPS",IF(K7="Staff drop-off","STAFF_DROPOFF",IF(K7="Replacements","REPLACEMENT",IF(K7="Central Stores Dispatch","CENTRAL STORES DISPATCH",IFNA(IFNA(VLOOKUP(F7,'Raw Platform Nov 4-6 2025'!C:C,1,FALSE),VLOOKUP(F7,'Raw Platform Nov 4-6 2025'!D:D,1,FALSE)),IFNA(VLOOKUP(F7,'Glovo Raw Nov 4-6 2025'!B:B,1,FALSE),"Not Matched")))))) | H7: =COUNTIF(F:F,F7) | I7: Nov 6, 2025, 6:07:30 PM | J7: Uber Eats | K7: PAID | L7: NATALIE N | M7: +491602097107 | N7: Pleasant View Villas, Shanzu Road, Nairobi, Kenya | O7: 12.0 | P7: 4.0 | Q7: 0 | R7: BICYCLE | S7: Little Italy | T7: false | U7: true | V7: Nov 6, 2025, 6:14:27 PM | X7: 0
A8: nsk-copy | B8: +2540794092505 | C8: Abdulaziz Juma Ebikes | D8: NSK NRB | E8: COMPLETED | F8: A31AC | G8: =IF(K8="Pick-up","PICKUPS",IF(K8="Staff drop-off","STAFF_DROPOFF",IF(K8="Replacements","REPLACEMENT",IF(K8="Central Stores Dispatch","CENTRAL STORES DISPATCH",IFNA(IFNA(VLOOKUP(F8,'Raw Platform Nov 4-6 2025'!C:C,1,FALSE),VLOOKUP(F8,'Raw Platform Nov 4-6 2025'!D:D,1,FALSE)),IFNA(VLOOKUP(F8,'Glovo Raw Nov 4-6 2025'!B:B,1,FALSE),"Not Matched")))))) | H8: =COUNTIF(F:F,F8) | I8: Nov 6, 2025, 5:39:24 PM | J8: Uber Eats | K8: UNPAID | L8: WINNIE A | M8: 0722587621 | N8: The Piano, Brookside Drive, Nairobi, Kenya | O8: 6.0 | P8: 1.8 | Q8: 996 | R8: BICYCLE | S8: Little Italy | T8: false | U8: true | V8: Nov 6, 2025, 5:41:01 PM | X8: 0
A9: nsk-copy | B9: +2540794092505 | C9: Abdulaziz Juma Ebikes | D9: NSK NRB | E9: COMPLETED | F9: 2CAF1 | G9: =IF(K9="Pick-up","PICKUPS",IF(K9="Staff drop-off","STAFF_DROPOFF",IF(K9="Replacements","REPLACEMENT",IF(K9="Central Stores Dispatch","CENTRAL STORES DISPATCH",IFNA(IFNA(VLOOKUP(F9,'Raw Platform Nov 4-6 2025'!C:C,1,FALSE),VLOOKUP(F9,'Raw Platform Nov 4-6 2025'!D:D,1,FALSE)),IFNA(VLOOKUP(F9,'Glovo Raw Nov 4-6 2025'!B:B,1,FALSE),"Not Matched")))))) | H9: =COUNTIF(F:F,F9) | I9: Nov 6, 2025, 5:04:11 PM | J9: Uber Eats | K9: PAID | L9: LIA B | M9: 0708763422 | N9: 87 Rhapta Road, Nairobi, Kenya | O9: 5.0 | P9: 1.9 | Q9: 0 | R9: BICYCLE | S9: Little Italy | T9: false | U9: true | V9: Nov 6, 2025, 5:09:19 PM | X9: 0
A10: nsk | B10: +2540794092505 | C10: Abdulaziz Juma Ebikes | D10: NSK NRB | E10: COMPLETED | F10: 101477071505 | G10: =IF(K10="Pick-up","PICKUPS",IF(K10="Staff drop-off","STAFF_DROPOFF",IF(K10="Replacements","REPLACEMENT",IF(K10="Central Stores Dispatch","CENTRAL STORES DISPATCH",IFNA(IFNA(VLOOKUP(F10,'Raw Platform Nov 4-6 2025'!C:C,1,FALSE),VLOOKUP(F10,'Raw Platform Nov 4-6 2025'!D:D,1,FALSE)),IFNA(VLOOKUP(F10,'Glovo Raw Nov 4-6 2025'!B:B,1,FALSE),"Not Matched")))))) | H10: =COUNTIF(F:F,F10) | I10: Nov 6, 2025, 4:57:57 PM | J10: Glovo | K10: PAID | L10: INES | M10: 0758992983 | N10: McKinsey & Company Inc, Mzima Springs Lane, Nairobi, Kenya | O10: 10.0 | P10: 5.9 | Q10: 0 | R10: BICYCLE | S10: Siam - Thai Kitchen | T10: false | U10: true | V10: Nov 6, 2025, 4:59:35 PM | X10: 0
A11: nsk | B11: +2540794092505 | C11: Abdulaziz Juma Ebikes | D11: NSK NRB | E11: COMPLETED | F11: FF96A | G11: =IF(K11="Pick-up","PICKUPS",IF(K11="Staff drop-off","STAFF_DROPOFF",IF(K11="Replacements","REPLACEMENT",IF(K11="Central Stores Dispatch","CENTRAL STORES DISPATCH",IFNA(IFNA(VLOOKUP(F11,'Raw Platform Nov 4-6 2025'!C:C,1,FALSE),VLOOKUP(F11,'Raw Platform Nov 4-6 2025'!D:D,1,FALSE)),IFNA(VLOOKUP(F11,'Glovo Raw Nov 4-6 2025'!B:B,1,FALSE),"Not Matched")))))) | H11: =COUNTIF(F:F,F11) | I11: Nov 6, 2025, 4:55:00 PM | J11: Uber Eats | K11: PAID | L11: MAXIME S | M11: 0758992983 | N11: Delta Riverside Office Park, Riverside Drive, Nairobi, Kenya | O11: 6.0 | P11: 2.1 | Q11: 0 | R11: BICYCLE | S11: Siam - Thai Kitchen | T11: false | U11: true | V11: Nov 6, 2025, 5:00:47 PM | X11: 0
A12: nsk-copy | B12: +2540794092505 | C12: Abdulaziz Juma Ebikes | D12: NSK NRB | E12: COMPLETED | F12: A6151 | G12: =IF(K12="Pick-up","PICKUPS",IF(K12="Staff drop-off","STAFF_DROPOFF",IF(K12="Replacements","REPLACEMENT",IF(K12="Central Stores Dispatch","CENTRAL STORES DISPATCH",IFNA(IFNA(VLOOKUP(F12,'Raw Platform Nov 4-6 2025'!C:C,1,FALSE),VLOOKUP(F12,'Raw Platform Nov 4-6 2025'!D:D,1,FALSE)),IFNA(VLOOKUP(F12,'Glovo Raw Nov 4-6 2025'!B:B,1,FALSE),"Not Matched")))))) | H12: =COUNTIF(F:F,F12) | I12: Nov 6, 2025, 3:40:45 PM | J12: Uber Eats | K12: PAID | L12: AYAN M | M12: 0705252321 | N12: Clock Tower Suites, Mpaka Road, Nairobi, Kenya | O12: 7.0 | P12: 2.3 | Q12: 0 | R12: BICYCLE | S12: Little Italy | T12: false | U12: true | V12: Nov 6, 2025, 4:11:52 PM | X12: 0
A13: nsk-copy | B13: +2540794092505 | C13: Abdulaziz Juma Ebikes | D13: NSK NRB | E13: COMPLETED | F13: 64A37 | G13: =IF(K13="Pick-up","PICKUPS",IF(K13="Staff drop-off","STAFF_DROPOFF",IF(K13="Replacements","REPLACEMENT",IF(K13="Central Stores Dispatch","CENTRAL STORES DISPATCH",IFNA(IFNA(VLOOKUP(F13,'Raw Platform Nov 4-6 2025'!C:C,1,FALSE),VLOOKUP(F13,'Raw Platform Nov 4-6 2025'!D:D,1,FALSE)),IFNA(VLOOKUP(F13,'Glovo Raw Nov 4-6 2025'!B:B,1,FALSE),"Not Matched")))))) | H13: =COUNTIF(F:F,F13) | I13: Nov 6, 2025, 1:30:12 PM | J13: Uber Eats | K13: PAID | L13: SAMPA S | M13: +254116639992 | N13: Le'Mac, Church Road, Nairobi, Kenya | O13: 7.0 | P13: 3.0 | Q13: 0 | R13: BICYCLE | S13: Little Italy | T13: false | U13: true | V13: Nov 6, 2025, 1:35:15 PM | X13: 0
... A61: westlands | B61: +2540707098612 | C61: Benard Ogada | D61: Westlands NRB | E61: COMPLETED | F61: 95F5D | G61: =IF(K61="Pick-up","PICKUPS",IF(K61="Staff drop-off","STAFF_DROPOFF",IF(K61="Replacements","REPLACEMENT",IF(K61="Central Stores Dispatch","CENTRAL STORES DISPATCH",IFNA(IFNA(VLOOKUP(F61,'Raw Platform Nov 4-6 2025'!C:C,1,FALSE),VLOOKUP(F61,'Raw Platform Nov 4-6 2025'!D:D,1,FALSE)),IFNA(VLOOKUP(F61,'Glovo Raw Nov 4-6 2025'!B:B,1,FALSE),"Not Matched")))))) | H61: =COUNTIF(F:F,F61) | I61: Nov 6, 2025, 7:50:00 PM | J61: Uber Eats | K61: PAID | L61: Noreen | M61: 0705030903 | N61: Gatundu Crescent, Nairobi, Kenya | O61: 11.0 | P61: 4.5 | Q61: 0 | R61: MOTORCYCLE | S61: DILLI! - Curries & Grill | T61: false | U61: true | V61: Nov 6, 2025, 8:09:18 PM | X61: 146
A62: purvi-auro | B62: +2540707098612 | C62: Benard Ogada | E62: COMPLETED | F62: CF95B | G62: =IF(K62="Pick-up","PICKUPS",IF(K62="Staff drop-off","STAFF_DROPOFF",IF(K62="Replacements","REPLACEMENT",IF(K62="Central Stores Dispatch","CENTRAL STORES DISPATCH",IFNA(IFNA(VLOOKUP(F62,'Raw Platform Nov 4-6 2025'!C:C,1,FALSE),VLOOKUP(F62,'Raw Platform Nov 4-6 2025'!D:D,1,FALSE)),IFNA(VLOOKUP(F62,'Glovo Raw Nov 4-6 2025'!B:B,1,FALSE),"Not Matched")))))) | H62: =COUNTIF(F:F,F62) | I62: Nov 6, 2025, 6:57:16 PM | J62: Uber Eats | K62: PAID | L62: Elizabeth W | M62: 0714266979 | N62: Enaki Resort Residence, Nairobi, Kenya | O62: 14.0 | P62: 9.6 | Q62: 0 | R62: MOTORCYCLE | T62: false | U62: true | V62: Nov 6, 2025, 7:06:35 PM | X62: 263.3
A63: westlands | B63: +2540707098612 | C63: Benard Ogada | D63: Westlands NRB | E63: COMPLETED | F63: 101477381676 | G63: =IF(K63="Pick-up","PICKUPS",IF(K63="Staff drop-off","STAFF_DROPOFF",IF(K63="Replacements","REPLACEMENT",IF(K63="Central Stores Dispatch","CENTRAL STORES DISPATCH",IFNA(IFNA(VLOOKUP(F63,'Raw Platform Nov 4-6 2025'!C:C,1,FALSE),VLOOKUP(F63,'Raw Platform Nov 4-6 2025'!D:D,1,FALSE)),IFNA(VLOOKUP(F63,'Glovo Raw Nov 4-6 2025'!B:B,1,FALSE),"Not Matched")))))) | H63: =COUNTIF(F:F,F63) | I63: Nov 6, 2025, 5:56:25 PM | J63: Glovo | K63: PAID | L63: FREDERICK | M63: 0796757063 | N63: City Oasis Gardens, Argwings Kodhek Road, Nairobi, Kenya | O63: 14.0 | P63: 6.1 | Q63: 0 | R63: MOTORCYCLE | S63: Khan's Pakistani Kitchen | T63: false | U63: true | V63: Nov 6, 2025, 6:19:44 PM | X63: 182.8
A64: nsk | B64: +2540707098612 | C64: Benard Ogada | D64: NSK NRB | E64: COMPLETED | F64: 00909 | G64: =IF(K64="Pick-up","PICKUPS",IF(K64="Staff drop-off","STAFF_DROPOFF",IF(K64="Replacements","REPLACEMENT",IF(K64="Central Stores Dispatch","CENTRAL STORES DISPATCH",IFNA(IFNA(VLOOKUP(F64,'Raw Platform Nov 4-6 2025'!C:C,1,FALSE),VLOOKUP(F64,'Raw Platform Nov 4-6 2025'!D:D,1,FALSE)),IFNA(VLOOKUP(F64,'Glovo Raw Nov 4-6 2025'!B:B,1,FALSE),"Not Matched")))))) | H64: =COUNTIF(F:F,F64) | I64: Nov 6, 2025, 5:09:56 PM | J64: Uber Eats | K64: PAID | L64: CHANIA F | M64: 0758992983 | N64: McKinsey & Company Inc, Mzima Springs Lane, Nairobi, Kenya | O64: 10.0 | P64: 5.9 | Q64: 0 | R64: MOTORCYCLE | S64: Siam - Thai Kitchen | T64: false | U64: true | V64: Nov 6, 2025, 5:51:13 PM | X64: 178.2
A65: westlands | B65: +2540707098612 | C65: Benard Ogada | D65: Westlands NRB | E65: COMPLETED | F65: 394A9 | G65: =IF(K65="Pick-up","PICKUPS",IF(K65="Staff drop-off","STAFF_DROPOFF",IF(K65="Replacements","REPLACEMENT",IF(K65="Central Stores Dispatch","CENTRAL STORES DISPATCH",IFNA(IFNA(VLOOKUP(F65,'Raw Platform Nov 4-6 2025'!C:C,1,FALSE),VLOOKUP(F65,'Raw Platform Nov 4-6 2025'!D:D,1,FALSE)),IFNA(VLOOKUP(F65,'Glovo Raw Nov 4-6 2025'!B:B,1,FALSE),"Not Matched")))))) | H65: =COUNTIF(F:F,F65) | I65: Nov 6, 2025, 3:12:00 PM | J65: Uber Eats | K65: UNPAID | L65: Zakaria | M65: 0712883411 | N65: Sky View Heights, Nairobi, Kenya | O65: 19.0 | P65: 17.2 | Q65: 1590 | R65: MOTORCYCLE | S65: Marty's Famous Burgers | T65: false | U65: true | V65: Nov 6, 2025, 3:34:20 PM | X65: 438.1
A66: westlands | B66: +2540707098612 | C66: Benard Ogada | D66: Westlands NRB | E66: COMPLETED | F66: F1CC6 | G66: =IF(K66="Pick-up","PICKUPS",IF(K66="Staff drop-off","STAFF_DROPOFF",IF(K66="Replacements","REPLACEMENT",IF(K66="Central Stores Dispatch","CENTRAL STORES DISPATCH",IFNA(IFNA(VLOOKUP(F66,'Raw Platform Nov 4-6 2025'!C:C,1,FALSE),VLOOKUP(F66,'Raw Platform Nov 4-6 2025'!D:D,1,FALSE)),IFNA(VLOOKUP(F66,'Glovo Raw Nov 4-6 2025'!B:B,1,FALSE),"Not Matched")))))) | H66: =COUNTIF(F:F,F66) | I66: Nov 6, 2025, 1:56:24 PM | J66: Uber Eats | K66: PAID | L66: DABIEL O | M66: 0716112660 | N66: McKinsey & Company Inc, Mzima Springs Lane, Nairobi, Kenya | O66: 10.0 | P66: 5.8 | Q66: 0 | R66: MOTORCYCLE | S66: Khan's Pakistani Kitchen | T66: false | U66: true | V66: Nov 6, 2025, 2:14:44 PM | X66: 175.9
A67: nsk-copy | B67: +2540707098612 | C67: Benard Ogada | D67: NSK NRB | E67: COMPLETED | F67: PICKUPMILK,0,M | G67: =IF(K67="Pick-up","PICKUPS",IF(K67="Staff drop-off","STAFF_DROPOFF",IF(K67="Replacements","REPLACEMENT",IF(K67="Central Stores Dispatch","CENTRAL STORES DISPATCH",IFNA(IFNA(VLOOKUP(F67,'Raw Platform Nov 4-6 2025'!C:C,1,FALSE),VLOOKUP(F67,'Raw Platform Nov 4-6 2025'!D:D,1,FALSE)),IFNA(VLOOKUP(F67,'Glovo Raw Nov 4-6 2025'!B:B,1,FALSE),"Not Matched")))))) | H67: =COUNTIF(F:F,F67) | I67: Nov 6, 2025, 12:55:45 PM | J67: Pick-up | K67: PAID | L67: L.ITALY | M67: 0115133474 | N67: Purvi House, Nairobi, Kenya | O67: 0.0 | P67: 0.0 | Q67: 0 | R67: MOTORCYCLE | S67: Pick- Ups | T67: false | U67: true | V67: Nov 6, 2025, 12:56:59 PM | X67: 100
A68: nsk-copy | B68: +2540707098612 | C68: Benard Ogada | D68: NSK NRB | E68: COMPLETED | F68: B4C22 | G68: =IF(K68="Pick-up","PICKUPS",IF(K68="Staff drop-off","STAFF_DROPOFF",IF(K68="Replacements","REPLACEMENT",IF(K68="Central Stores Dispatch","CENTRAL STORES DISPATCH",IFNA(IFNA(VLOOKUP(F68,'Raw Platform Nov 4-6 2025'!C:C,1,FALSE),VLOOKUP(F68,'Raw Platform Nov 4-6 2025'!D:D,1,FALSE)),IFNA(VLOOKUP(F68,'Glovo Raw Nov 4-6 2025'!B:B,1,FALSE),"Not Matched")))))) | H68: =COUNTIF(F:F,F68) | I68: Nov 6, 2025, 12:35:19 PM | J68: Uber Eats | K68: PAID | L68: ALLAN M | M68: 0705474946 | N68: Financial Sector Deepening Africa - FSD Africa, Riverside Drive, Nairobi, Kenya | O68: 6.0 | P68: 2.3 | Q68: 0 | R68: MOTORCYCLE | S68: Little Italy | T68: false | U68: true | V68: Nov 6, 2025, 12:57:29 PM | X68: 100
A69: westlands | B69: +2540707098612 | C69: Benard Ogada | D69: Westlands NRB | E69: COMPLETED | F69: F29C2 | G69: =IF(K69="Pick-up","PICKUPS",IF(K69="Staff drop-off","STAFF_DROPOFF",IF(K69="Replacements","REPLACEMENT",IF(K69="Central Stores Dispatch","CENTRAL STORES DISPATCH",IFNA(IFNA(VLOOKUP(F69,'Raw Platform Nov 4-6 2025'!C:C,1,FALSE),VLOOKUP(F69,'Raw Platform Nov 4-6 2025'!D:D,1,FALSE)),IFNA(VLOOKUP(F69,'Glovo Raw Nov 4-6 2025'!B:B,1,FALSE),"Not Matched")))))) | H69: =COUNTIF(F:F,F69) | I69: Nov 6, 2025, 11:37:06 AM | J69: Uber Eats | K69: PAID | L69: Katherine m | M69: 0793535213 | N69: Krishna Views Apartment, General Mathenge Road, Nairobi, Kenya | O69: 9.0 | P69: 2.8 | Q69: 0 | R69: MOTORCYCLE | S69: DILLI! - Curries & Grill | T69: false | U69: true | V69: Nov 6, 2025, 12:15:39 PM | X69: 106.9
A70: westlands | B70: +2540707098612 | C70: Benard Ogada | D70: Westlands NRB | E70: COMPLETED | F70: 52B6D | G70: =IF(K70="Pick-up","PICKUPS",IF(K70="Staff drop-off","STAFF_DROPOFF",IF(K70="Replacements","REPLACEMENT",IF(K70="Central Stores Dispatch","CENTRAL STORES DISPATCH",IFNA(IFNA(VLOOKUP(F70,'Raw Platform Nov 4-6 2025'!C:C,1,FALSE),VLOOKUP(F70,'Raw Platform Nov 4-6 2025'!D:D,1,FALSE)),IFNA(VLOOKUP(F70,'Glovo Raw Nov 4-6 2025'!B:B,1,FALSE),"Not Matched")))))) | H70: =COUNTIF(F:F,F70) | I70: Nov 5, 2025, 6:39:24 PM | J70: Uber Eats | K70: PAID | L70: SAHER A | M70: 0741551950 | N70: The Soho Serviced Apartments, Kirichwa Road, Nairobi, Kenya | O70: 15.0 | P70: 6.1 | Q70: 0 | R70: MOTORCYCLE | S70: Khan's Pakistani Kitchen | T70: false | U70: true | V70: Nov 5, 2025, 6:55:30 PM | X70: 182.8
A71: westlands | B71: +2540707098612 | C71: Benard Ogada | D71: Westlands NRB | E71: COMPLETED | F71: 1.01476355587E11 | G71: =IF(K71="Pick-up","PICKUPS",IF(K71="Staff drop-off","STAFF_DROPOFF",IF(K71="Replacements","REPLACEMENT",IF(K71="Central Stores Dispatch","CENTRAL STORES DISPATCH",IFNA(IFNA(VLOOKUP(F71,'Raw Platform Nov 4-6 2025'!C:C,1,FALSE),VLOOKUP(F71,'Raw Platform Nov 4-6 2025'!D:D,1,FALSE)),IFNA(VLOOKUP(F71,'Glovo Raw Nov 4-6 2025'!B:B,1,FALSE),"Not Matched")))))) | H71: =COUNTIF(F:F,F71) | I71: Nov 5, 2025, 3:24:46 PM | J71: Glovo | K71: PAID | L71: SADIA-amedsadia | M71: 0725144794 | N71: Business Bay Square (BBS Mall), General Waruingi Road, Nairobi, Kenya | O71: 11.0 | P71: 6.9 | Q71: 0 | R71: MOTORCYCLE | S71: ANDO Kitchens | T71: false | U71: true | V71: Nov 5, 2025, 3:27:07 PM | X71: 201.2
A72: westlands | B72: +2540707098612 | C72: Benard Ogada | D72: Westlands NRB | E72: COMPLETED | F72: kilimani(75ML)5.11 | G72: =IF(K72="Pick-up","PICKUPS",IF(K72="Staff drop-off","STAFF_DROPOFF",IF(K72="Replacements","REPLACEMENT",IF(K72="Central Stores Dispatch","CENTRAL STORES DISPATCH",IFNA(IFNA(VLOOKUP(F72,'Raw Platform Nov 4-6 2025'!C:C,1,FALSE),VLOOKUP(F72,'Raw Platform Nov 4-6 2025'!D:D,1,FALSE)),IFNA(VLOOKUP(F72,'Glovo Raw Nov 4-6 2025'!B:B,1,FALSE),"Not Matched")))))) | H72: =COUNTIF(F:F,F72) | I72: Nov 5, 2025, 2:23:34 PM | J72: Central Stores Dispatch | K72: PAID | L72: PROCUMENT/ | M72: 0795148192 | N72: B-Arcade Mall, Kilimani, Argwings Kodhek Road, Nairobi, Kenya | O72: 13.0 | P72: 6.4 | Q72: 0 | R72: MOTORCYCLE | S72: Pick- Ups | T72: false | U72: true | V72: Nov 5, 2025, 2:24:49 PM | X72: 189.7
A73: westlands-copy-2 | B73: +2540707098612 | C73: Benard Ogada | D73: Kilimani NRB | E73: COMPLETED | F73: 1:57PICKUP | G73: =IF(K73="Pick-up","PICKUPS",IF(K73="Staff drop-off","STAFF_DROPOFF",IF(K73="Replacements","REPLACEMENT",IF(K73="Central Stores Dispatch","CENTRAL STORES DISPATCH",IFNA(IFNA(VLOOKUP(F73,'Raw Platform Nov 4-6 2025'!C:C,1,FALSE),VLOOKUP(F73,'Raw Platform Nov 4-6 2025'!D:D,1,FALSE)),IFNA(VLOOKUP(F73,'Glovo Raw Nov 4-6 2025'!B:B,1,FALSE),"Not Matched")))))) | H73: =COUNTIF(F:F,F73) | I73: Nov 5, 2025, 1:57:34 PM | J73: Pick-up | K73: PAID | L73: KILIMANI | M73: 0769304599 | N73: Purvi House, Nairobi, Kenya | O73: 16.0 | P73: 7.1 | Q73: 0 | R73: MOTORCYCLE | S73: ANDO Kitchens | T73: false | U73: true | V73: Nov 5, 2025, 1:58:11 PM | X73: 205.8
A74: westlands | B74: +2540707098612 | C74: Benard Ogada | D74: Westlands NRB | E74: COMPLETED | F74: 11E9A | G74: =IF(K74="Pick-up","PICKUPS",IF(K74="Staff drop-off","STAFF_DROPOFF",IF(K74="Replacements","REPLACEMENT",IF(K74="Central Stores Dispatch","CENTRAL STORES DISPATCH",IFNA(IFNA(VLOOKUP(F74,'Raw Platform Nov 4-6 2025'!C:C,1,FALSE),VLOOKUP(F74,'Raw Platform Nov 4-6 2025'!D:D,1,FALSE)),IFNA(VLOOKUP(F74,'Glovo Raw Nov 4-6 2025'!B:B,1,FALSE),"Not Matched")))))) | H74: =COUNTIF(F:F,F74) | I74: Nov 5, 2025, 1:05:00 PM | J74: Uber Eats | K74: PAID | L74: DAMARIS | M74: 0790430137 | N74: Malakal Court, Westlands Avenue, Nairobi, Kenya | O74: 4.0 | P74: 1.5 | Q74: 0 | R74: MOTORCYCLE | S74: Marty's Famous Burgers | T74: false | U74: true | V74: Nov 5, 2025, 1:25:34 PM | X74: 100
... A184: nsk-copy | B184: +254790564971 | C184: Chrispine Omondi | D184: NSK NRB | E184: COMPLETED | F184: PICKUPCHEESE345776 | G184: =IF(K184="Pick-up","PICKUPS",IF(K184="Staff drop-off","STAFF_DROPOFF",IF(K184="Replacements","REPLACEMENT",IF(K184="Central Stores Dispatch","CENTRAL STORES DISPATCH",IFNA(IFNA(VLOOKUP(F184,'Raw Platform Nov 4-6 2025'!C:C,1,FALSE),VLOOKUP(F184,'Raw Platform Nov 4-6 2025'!D:D,1,FALSE)),IFNA(VLOOKUP(F184,'Glovo Raw Nov 4-6 2025'!B:B,1,FALSE),"Not Matched")))))) | H184: =COUNTIF(F:F,F184) | I184: Nov 4, 2025, 3:01:21 PM | J184: Pick-up | K184: PAID | L184: L.ITALY | M184: 0115133474 | N184: B-Arcade Mall, Kilimani, Argwings Kodhek Road, Nairobi, Kenya | O184: 14.0 | P184: 6.5 | Q184: 0 | R184: CAR | S184: Little Italy | T184: false | U184: true | V184: Nov 4, 2025, 3:02:52 PM | X184: 192
A185: steady-pizza-chicken-house | B185: +250783568521 | C185: Cyprien Nsengiyaremye | E185: COMPLETED | F185: 139579 | G185: =IF(K185="Pick-up","PICKUPS",IF(K185="Staff drop-off","STAFF_DROPOFF",IF(K185="Replacements","REPLACEMENT",IF(K185="Central Stores Dispatch","CENTRAL STORES DISPATCH",IFNA(IFNA(VLOOKUP(F185,'Raw Platform Nov 4-6 2025'!C:C,1,FALSE),VLOOKUP(F185,'Raw Platform Nov 4-6 2025'!D:D,1,FALSE)),IFNA(VLOOKUP(F185,'Glovo Raw Nov 4-6 2025'!B:B,1,FALSE),"Not Matched")))))) | H185: =COUNTIF(F:F,F185) | I185: Nov 4, 2025, 7:22:00 PM | J185: Ando App | K185: UNPAID | L185: stella kaniaru | M185: +250791591916 | N185: Biryogo Car Free Zone, Macoco restaurant | O185: 21.0 | P185: 10.6 | Q185: 1500 | R185: BICYCLE | T185: false | U185: true | V185: Nov 4, 2025, 8:18:26 PM | X185: 2000
A186: pad-thai-restaurant | B186: +250783568521 | C186: Cyprien Nsengiyaremye | E186: REJECTED | F186: 138783 | G186: =IF(K186="Pick-up","PICKUPS",IF(K186="Staff drop-off","STAFF_DROPOFF",IF(K186="Replacements","REPLACEMENT",IF(K186="Central Stores Dispatch","CENTRAL STORES DISPATCH",IFNA(IFNA(VLOOKUP(F186,'Raw Platform Nov 4-6 2025'!C:C,1,FALSE),VLOOKUP(F186,'Raw Platform Nov 4-6 2025'!D:D,1,FALSE)),IFNA(VLOOKUP(F186,'Glovo Raw Nov 4-6 2025'!B:B,1,FALSE),"Not Matched")))))) | H186: =COUNTIF(F:F,F186) | I186: Nov 4, 2025, 7:11:58 PM | J186: Ando App | K186: UNPAID | L186: MAHORO Geofrey | M186: +250795019129 | N186: Kigali | O186: 20.0 | P186: 10.0 | Q186: 15000 | R186: BICYCLE | T186: false | U186: false | V186: Nov 4, 2025, 8:14:19 PM | X186: 0
A187: westlands-copy-2 | B187: +254748392704 | C187: Daniel Namaswa | D187: Kilimani NRB | E187: COMPLETED | F187: 101477514113 | G187: =IF(K187="Pick-up","PICKUPS",IF(K187="Staff drop-off","STAFF_DROPOFF",IF(K187="Replacements","REPLACEMENT",IF(K187="Central Stores Dispatch","CENTRAL STORES DISPATCH",IFNA(IFNA(VLOOKUP(F187,'Raw Platform Nov 4-6 2025'!C:C,1,FALSE),VLOOKUP(F187,'Raw Platform Nov 4-6 2025'!D:D,1,FALSE)),IFNA(VLOOKUP(F187,'Glovo Raw Nov 4-6 2025'!B:B,1,FALSE),"Not Matched")))))) | H187: =COUNTIF(F:F,F187) | I187: Nov 6, 2025, 8:16:04 PM | J187: Glovo | K187: PAID | L187: TIFFANY | M187: 0706282867 | N187: Dolphine studio apartments, Kahuho, Nairobi, Kenya | O187: 26.0 | P187: 9.0 | Q187: 0 | R187: MOTORCYCLE | S187: Marty's Famous Burgers | T187: false | U187: true | V187: Nov 6, 2025, 8:37:40 PM | X187: 249.5
A188: westlands-copy-2 | B188: +254748392704 | C188: Daniel Namaswa | D188: Kilimani NRB | E188: COMPLETED | F188: CC8AF | G188: =IF(K188="Pick-up","PICKUPS",IF(K188="Staff drop-off","STAFF_DROPOFF",IF(K188="Replacements","REPLACEMENT",IF(K188="Central Stores Dispatch","CENTRAL STORES DISPATCH",IFNA(IFNA(VLOOKUP(F188,'Raw Platform Nov 4-6 2025'!C:C,1,FALSE),VLOOKUP(F188,'Raw Platform Nov 4-6 2025'!D:D,1,FALSE)),IFNA(VLOOKUP(F188,'Glovo Raw Nov 4-6 2025'!B:B,1,FALSE),"Not Matched")))))) | H188: =COUNTIF(F:F,F188) | I188: Nov 6, 2025, 6:56:35 PM | J188: Uber Eats | K188: PAID | L188: CALVIN M. | M188: 0722165694 | N188: Racecourse Gardens Apartments, Mama Wahu Road, Nairobi, Kenya | O188: 16.0 | P188: 6.7 | Q188: 0 | R188: MOTORCYCLE | S188: ANDO Kitchens | T188: false | U188: true | V188: Nov 6, 2025, 7:39:19 PM | X188: 196.6
A189: westlands-copy-2 | B189: +254748392704 | C189: Daniel Namaswa | D189: AURO | E189: COMPLETED | F189: 5A454 | G189: =IF(K189="Pick-up","PICKUPS",IF(K189="Staff drop-off","STAFF_DROPOFF",IF(K189="Replacements","REPLACEMENT",IF(K189="Central Stores Dispatch","CENTRAL STORES DISPATCH",IFNA(IFNA(VLOOKUP(F189,'Raw Platform Nov 4-6 2025'!C:C,1,FALSE),VLOOKUP(F189,'Raw Platform Nov 4-6 2025'!D:D,1,FALSE)),IFNA(VLOOKUP(F189,'Glovo Raw Nov 4-6 2025'!B:B,1,FALSE),"Not Matched")))))) | H189: =COUNTIF(F:F,F189) | I189: Nov 6, 2025, 5:53:26 PM | J189: Uber Eats | K189: PAID | L189: SHAN W. | M189: 0111627411 | N189: The Soho Serviced Apartments, Kirichwa Road, Nairobi, Kenya | O189: 5.0 | P189: 1.2 | Q189: 0 | R189: MOTORCYCLE | S189: KAI The Sushi Bar | T189: false | U189: true | V189: Nov 6, 2025, 6:30:29 PM | X189: 100
A190: westlands-copy-2 | B190: +254748392704 | C190: Daniel Namaswa | D190: Kilimani NRB | E190: COMPLETED | F190: 4788.0 | G190: =IF(K190="Pick-up","PICKUPS",IF(K190="Staff drop-off","STAFF_DROPOFF",IF(K190="Replacements","REPLACEMENT",IF(K190="Central Stores Dispatch","CENTRAL STORES DISPATCH",IFNA(IFNA(VLOOKUP(F190,'Raw Platform Nov 4-6 2025'!C:C,1,FALSE),VLOOKUP(F190,'Raw Platform Nov 4-6 2025'!D:D,1,FALSE)),IFNA(VLOOKUP(F190,'Glovo Raw Nov 4-6 2025'!B:B,1,FALSE),"Not Matched")))))) | H190: =COUNTIF(F:F,F190) | I190: Nov 6, 2025, 5:00:05 PM | J190: Uber Eats | K190: PAID | L190: KARL | M190: 0792358430 | N190: Mugumo Village, Nairobi, Kenya | O190: 9.0 | P190: 3.3 | Q190: 0 | R190: MOTORCYCLE | S190: Marty's Famous Burgers | T190: false | U190: true | V190: Nov 6, 2025, 5:01:33 PM | X190: 118.4
A191: westlands-copy-2 | B191: +254748392704 | C191: Daniel Namaswa | D191: Kilimani NRB | E191: COMPLETED | F191: DD3B3 | G191: =IF(K191="Pick-up","PICKUPS",IF(K191="Staff drop-off","STAFF_DROPOFF",IF(K191="Replacements","REPLACEMENT",IF(K191="Central Stores Dispatch","CENTRAL STORES DISPATCH",IFNA(IFNA(VLOOKUP(F191,'Raw Platform Nov 4-6 2025'!C:C,1,FALSE),VLOOKUP(F191,'Raw Platform Nov 4-6 2025'!D:D,1,FALSE)),IFNA(VLOOKUP(F191,'Glovo Raw Nov 4-6 2025'!B:B,1,FALSE),"Not Matched")))))) | H191: =COUNTIF(F:F,F191) | I191: Nov 6, 2025, 2:55:47 PM | J191: Uber Eats | K191: PAID | L191: JERMAINE C. | M191: 0796743688 | N191: GATUNDU HEIGHTS, Gatundu Road, Nairobi, Kenya | O191: 8.0 | P191: 2.6 | Q191: 0 | R191: MOTORCYCLE | S191: Little Italy | T191: false | U191: true | V191: Nov 6, 2025, 3:30:07 PM | X191: 102.3
A192: westlands-copy-2 | B192: +254748392704 | C192: Daniel Namaswa | D192: Kilimani NRB | E192: COMPLETED | F192: 58705 | G192: =IF(K192="Pick-up","PICKUPS",IF(K192="Staff drop-off","STAFF_DROPOFF",IF(K192="Replacements","REPLACEMENT",IF(K192="Central Stores Dispatch","CENTRAL STORES DISPATCH",IFNA(IFNA(VLOOKUP(F192,'Raw Platform Nov 4-6 2025'!C:C,1,FALSE),VLOOKUP(F192,'Raw Platform Nov 4-6 2025'!D:D,1,FALSE)),IFNA(VLOOKUP(F192,'Glovo Raw Nov 4-6 2025'!B:B,1,FALSE),"Not Matched")))))) | H192: =COUNTIF(F:F,F192) | I192: Nov 6, 2025, 1:52:16 PM | J192: Uber Eats | K192: PAID | L192: JOSEPH M. | M192: 0700545574 | N192: McKinsey & Company Inc, Mzima Springs Lane, Nairobi, Kenya | O192: 10.0 | P192: 4.2 | Q192: 0 | R192: MOTORCYCLE | S192: Siam - Thai Kitchen | T192: false | U192: true | V192: Nov 6, 2025, 2:06:54 PM | X192: 139.1
A193: westlands-copy-2 | B193: +254748392704 | C193: Daniel Namaswa | D193: Kilimani NRB | E193: COMPLETED | F193: 62305.0 | G193: =IF(K193="Pick-up","PICKUPS",IF(K193="Staff drop-off","STAFF_DROPOFF",IF(K193="Replacements","REPLACEMENT",IF(K193="Central Stores Dispatch","CENTRAL STORES DISPATCH",IFNA(IFNA(VLOOKUP(F193,'Raw Platform Nov 4-6 2025'!C:C,1,FALSE),VLOOKUP(F193,'Raw Platform Nov 4-6 2025'!D:D,1,FALSE)),IFNA(VLOOKUP(F193,'Glovo Raw Nov 4-6 2025'!B:B,1,FALSE),"Not Matched")))))) | H193: =COUNTIF(F:F,F193) | I193: Nov 6, 2025, 12:40:27 PM | J193: Uber Eats | K193: PAID | L193: ANN H | M193: 0718978238 | N193: Britam Tower, Nairobi, Kenya | O193: 10.0 | P193: 3.7 | Q193: 0 | R193: MOTORCYCLE | S193: Little Italy | T193: false | U193: true | V193: Nov 6, 2025, 1:05:24 PM | X193: 127.6
A194: westlands-copy-2 | B194: +254748392704 | C194: Daniel Namaswa | D194: Kilimani NRB | E194: COMPLETED | F194: E2FF3 | G194: =IF(K194="Pick-up","PICKUPS",IF(K194="Staff drop-off","STAFF_DROPOFF",IF(K194="Replacements","REPLACEMENT",IF(K194="Central Stores Dispatch","CENTRAL STORES DISPATCH",IFNA(IFNA(VLOOKUP(F194,'Raw Platform Nov 4-6 2025'!C:C,1,FALSE),VLOOKUP(F194,'Raw Platform Nov 4-6 2025'!D:D,1,FALSE)),IFNA(VLOOKUP(F194,'Glovo Raw Nov 4-6 2025'!B:B,1,FALSE),"Not Matched")))))) | H194: =COUNTIF(F:F,F194) | I194: Nov 6, 2025, 11:54:24 AM | J194: Uber Eats | K194: PAID | L194: RON S | M194: 0769304599 | N194: Mzima House, Nairobi, Kenya | O194: 10.0 | P194: 4.2 | Q194: 0 | R194: MOTORCYCLE | S194: Marty's Famous Burgers | T194: false | U194: true | V194: Nov 6, 2025, 12:12:08 PM | X194: 139.1
